Workbook

Sheet Loans
B1: Family Loan Master Sheet
B2: Income Source | C2: Amount (₹)
B3: Naresh | C3: 70000
B4: Veera | C4: 40000
B5: Total Income | C5: {=SUM(INDIRECT("C3:C"&ROW()-1))} -> 110000
B7: Loan Name | C7: Monthly EMI (₹) | D7: Category | E7: End Date | F7: EMIs Left (approx) | G7: Remaining Amount (₹) | H7: Notes
B8: SMFG Personal (Naresh) | C8: ₹26,494 | D8: Personal | E8: Apr 2031 | F8: 59 | G8: 1563146 | H8: 20% rate – highest cost loan
B9: SBI Personal (SivaPriya) | C9: 11839 | D9: Personal | E9: Jan 2028 | F9: 20 | G9: 236780 | H9: 21 EMIs left
B10: Equitas Home (Appa) | C10: 15250 | D10: Home Loan | E10: Dec 2030 | F10: 55 | G10: 838750 | H10: No prepayment penalty!
B11: Credit Card | C11: 18972 | D11: Credit Card | E11: Oct 2026 | F11: 5 | G11: 94860 | H11: Urgent – 36-48% interest!
B12: TVS Excel (Appa) | C12: 5087 | D12: Vehicle | E12: Jul 2027 | F12: 14 | G12: 71218 | H12: 15 EMIs left
B13: DIO Loan | C13: 5638 | D13: Vehicle | E13: Jul 2027 | F13: 14 | G13: 78932 | H13: 15 EMIs left
B14: Samasta 1 | C14: 3150 | D14: Microfinance | E14: Mar 2027 | F14: 10 | G14: 31500 | H14: 3rd Thu every month
B15: Samasta 2 | C15: 2650 | D15: Microfinance | E15: Jul 2026 | F15: 2 | G15: 5300 | H15: Ends Jul 2026 – almost done!
B16: Samasta 3 | C16: 2600 | D16: Microfinance | E16: Mar 2028 | F16: 22 | G16: 57200 | H16: 3rd Thu every month
B17: Samasta 4 | C17: 2680 | D17: Microfinance | E17: Apr 2028 | F17: 23 | G17: 61640 | H17: 3rd Thu every month
B18: ESAF 1 | C18: 5390 | D18: Microfinance | E18: Jan 2028 | F18: 20 | G18: 107800 | H18: 2nd Wed every month
B19: ESAF 2 | C19: 3235 | D19: Microfinance | E19: Oct 2027 | F19: 17 | G19: 54995 | H19: 2nd Wed every month
B20: ESAF 3 | C20: 1230 | D20: Microfinance | E20: Feb 2027 | F20: 9 | G20: 11070 | H20: 2nd Wed every month
... B24: Bajai EMI | C24: 1740 | D24: Bajai EMI | E24: DeC 2026 | F24: 6 | G24: 12590 | H24: Grinder & Fan
B25: TOTAL EMI / MONTH | C25: =SUM(C8:C24) -> 90401
B26: FREE CASH AFTER EMIs | C26: =C5-C25 -> 19599
B28: COLOR LEGEND
B29: Credit Card — URGENT (36-48% interest)
B30: Personal Loans
B31: Home Loan (no prepayment penalty)
B32: Vehicle Loans
B33: Microfinance / Small Loans

Sheet Monthly View
B1: Month-by-Month Payment View — May 2026 to Dec 2030
B2: Green cell = loan closes this month | Amber row = multiple closures | Blue row = car window (Jun 2027) | Red free cash = deficit
B4: Month | C4: Income | D4: Total EMI | E4: Expenses | F4: Free Cash | G4: Events | H4: SMFG Personal (Naresh) | I4: SBI Personal (SivaPriya) | J4: Equitas Home (Appa) | K4: Credit Card | L4: TVS Excel (Appa) | M4: DIO Loan | N4: Samasta 1 | O4: Samasta 2 | P4: Samasta 3 | Q4: Samasta 4 | R4: ESAF 1 | S4: ESAF 2 | T4: ESAF 3 | U4: Aasirvad 1 | V4: Aasirvad 1 2 | W4: Other Loan | X4: EMI
B5: Jun 2026 | C5: =Loans!$C$5 -> 110000 | D5: =SUM(H5:X5) -> 93336 | E5: =IF(B5="","",SUMIFS('June 2026 Expenses'!C:C, 'June 2026 Expenses'!A:A, ">="&DATEVALUE(B5), 'June 2026 Expenses'!A:A, "<="&EOMONTH(DATEVALUE(B5), 0))) -> 134263 | F5: =C5-D5-E5 -> -117599 | H5: 0 | I5: 11839 | J5: 15250 | K5: 18972 | L5: 4500 | M5: 5000 | N5: 3150 | O5: 2650 | P5: 2600 | Q5: 2680 | R5: 5390 | S5: 3235 | T5: 1230 | U5: 5920 | V5: 5920 | W5: 5000 | X5: 0
B6: Jul 2026 | C6: =Loans!$C$5 -> 110000 | D6: =SUM(H6:X6) -> 121570 | E6: =IF(B6="","",SUMIFS('June 2026 Expenses'!C:C, 'June 2026 Expenses'!A:A, ">="&DATEVALUE(B6), 'June 2026 Expenses'!A:A, "<="&EOMONTH(DATEVALUE(B6), 0))) -> 0 | F6: =C6-D6-E6 -> -11570 | G6: Samasta 2 closes ✓ | H6: 26494 | I6: 11839 | J6: 15250 | K6: 18972 | L6: 4500 | M6: 5000 | N6: 3150 | O6: 2650 | P6: 2600 | Q6: 2680 | R6: 5390 | S6: 3235 | T6: 1230 | U6: 5920 | V6: 5920 | W6: 5000 | X6: 1740
B7: Aug 2026 | C7: =Loans!$C$5 -> 110000 | D7: =SUM(H7:X7) -> 118920 | E7: =IF(B7="","",SUMIFS('June 2026 Expenses'!C:C, 'June 2026 Expenses'!A:A, ">="&DATEVALUE(B7), 'June 2026 Expenses'!A:A, "<="&EOMONTH(DATEVALUE(B7), 0))) -> 0 | F7: =C7-D7-E7 -> -8920 | H7: 26494 | I7: 11839 | J7: 15250 | K7: 18972 | L7: 4500 | M7: 5000 | N7: 3150 | P7: 2600 | Q7: 2680 | R7: 5390 | S7: 3235 | T7: 1230 | U7: 5920 | V7: 5920 | W7: 5000 | X7: 1740
B8: Sep 2026 | C8: =Loans!$C$5 -> 110000 | D8: =SUM(H8:X8) -> 118920 | E8: =IF(B8="","",SUMIFS('June 2026 Expenses'!C:C, 'June 2026 Expenses'!A:A, ">="&DATEVALUE(B8), 'June 2026 Expenses'!A:A, "<="&EOMONTH(DATEVALUE(B8), 0))) -> 0 | F8: =C8-D8-E8 -> -8920 | H8: 26494 | I8: 11839 | J8: 15250 | K8: 18972 | L8: 4500 | M8: 5000 | N8: 3150 | P8: 2600 | Q8: 2680 | R8: 5390 | S8: 3235 | T8: 1230 | U8: 5920 | V8: 5920 | W8: 5000 | X8: 1740
B9: Oct 2026 | C9: =Loans!$C$5 -> 110000 | D9: =SUM(H9:X9) -> 118920 | E9: =IF(B9="","",SUMIFS('June 2026 Expenses'!C:C, 'June 2026 Expenses'!A:A, ">="&DATEVALUE(B9), 'June 2026 Expenses'!A:A, "<="&EOMONTH(DATEVALUE(B9), 0))) -> 0 | F9: =C9-D9-E9 -> -8920 | G9: Credit Card closes ✓ | H9: 26494 | I9: 11839 | J9: 15250 | K9: 18972 | L9: 4500 | M9: 5000 | N9: 3150 | P9: 2600 | Q9: 2680 | R9: 5390 | S9: 3235 | T9: 1230 | U9: 5920 | V9: 5920 | W9: 5000 | X9: 1740
B10: Nov 2026 | C10: =Loans!$C$5 -> 110000 | D10: =SUM(H10:X10) -> 99948 | E10: =IF(B10="","",SUMIFS('June 2026 Expenses'!C:C, 'June 2026 Expenses'!A:A, ">="&DATEVALUE(B10), 'June 2026 Expenses'!A:A, "<="&EOMONTH(DATEVALUE(B10), 0))) -> 0 | F10: =C10-D10-E10 -> 10052 | H10: 26494 | I10: 11839 | J10: 15250 | L10: 4500 | M10: 5000 | N10: 3150 | P10: 2600 | Q10: 2680 | R10: 5390 | S10: 3235 | T10: 1230 | U10: 5920 | V10: 5920 | W10: 5000 | X10: 1740
B11: Dec 2026 | C11: =Loans!$C$5 -> 110000 | D11: =SUM(H11:X11) -> 99948 | E11: =IF(B11="","",SUMIFS('June 2026 Expenses'!C:C, 'June 2026 Expenses'!A:A, ">="&DATEVALUE(B11), 'June 2026 Expenses'!A:A, "<="&EOMONTH(DATEVALUE(B11), 0))) -> 0 | F11: =C11-D11-E11 -> 10052 | H11: 26494 | I11: 11839 | J11: 15250 | L11: 4500 | M11: 5000 | N11: 3150 | P11: 2600 | Q11: 2680 | R11: 5390 | S11: 3235 | T11: 1230 | U11: 5920 | V11: 5920 | W11: 5000 | X11: 1740
B12: Jan 2027 | C12: =Loans!$C$5 -> 110000 | D12: =SUM(H12:X12) -> 98208 | E12: =IF(B12="","",SUMIFS('June 2026 Expenses'!C:C, 'June 2026 Expenses'!A:A, ">="&DATEVALUE(B12), 'June 2026 Expenses'!A:A, "<="&EOMONTH(DATEVALUE(B12), 0))) -> 0 | F12: =C12-D12-E12 -> 11792 | H12: 26494 | I12: 11839 | J12: 15250 | L12: 4500 | M12: 5000 | N12: 3150 | P12: 2600 | Q12: 2680 | R12: 5390 | S12: 3235 | T12: 1230 | U12: 5920 | V12: 5920 | W12: 5000
B13: Feb 2027 | C13: =Loans!$C$5 -> 110000 | D13: =SUM(H13:X13) -> 98208 | E13: =IF(B13="","",SUMIFS('June 2026 Expenses'!C:C, 'June 2026 Expenses'!A:A, ">="&DATEVALUE(B13), 'June 2026 Expenses'!A:A, "<="&EOMONTH(DATEVALUE(B13), 0))) -> 0 | F13: =C13-D13-E13 -> 11792 | G13: ESAF 3 closes ✓ | H13: 26494 | I13: 11839 | J13: 15250 | L13: 4500 | M13: 5000 | N13: 3150 | P13: 2600 | Q13: 2680 | R13: 5390 | S13: 3235 | T13: 1230 | U13: 5920 | V13: 5920 | W13: 5000
B14: Mar 2027 | C14: =Loans!$C$5 -> 110000 | D14: =SUM(H14:X14) -> 96978 | E14: =IF(B14="","",SUMIFS('June 2026 Expenses'!C:C, 'June 2026 Expenses'!A:A, ">="&DATEVALUE(B14), 'June 2026 Expenses'!A:A, "<="&EOMONTH(DATEVALUE(B14), 0))) -> 0 | F14: =C14-D14-E14 -> 13022 | G14: Samasta 1 closes ✓ | H14: 26494 | I14: 11839 | J14: 15250 | L14: 4500 | M14: 5000 | N14: 3150 | P14: 2600 | Q14: 2680 | R14: 5390 | S14: 3235 | U14: 5920 | V14: 5920 | W14: 5000
B15: Apr 2027 | C15: =Loans!$C$5 -> 110000 | D15: =SUM(H15:X15) -> 93828 | E15: =IF(B15="","",SUMIFS('June 2026 Expenses'!C:C, 'June 2026 Expenses'!A:A, ">="&DATEVALUE(B15), 'June 2026 Expenses'!A:A, "<="&EOMONTH(DATEVALUE(B15), 0))) -> 0 | F15: =C15-D15-E15 -> 16172 | H15: 26494 | I15: 11839 | J15: 15250 | L15: 4500 | M15: 5000 | P15: 2600 | Q15: 2680 | R15: 5390 | S15: 3235 | U15: 5920 | V15: 5920 | W15: 5000
B16: May 2027 | C16: =Loans!$C$5 -> 110000 | D16: =SUM(H16:X16) -> 93828 | E16: =IF(B16="","",SUMIFS('June 2026 Expenses'!C:C, 'June 2026 Expenses'!A:A, ">="&DATEVALUE(B16), 'June 2026 Expenses'!A:A, "<="&EOMONTH(DATEVALUE(B16), 0))) -> 0 | F16: =C16-D16-E16 -> 16172 | H16: 26494 | I16: 11839 | J16: 15250 | L16: 4500 | M16: 5000 | P16: 2600 | Q16: 2680 | R16: 5390 | S16: 3235 | U16: 5920 | V16: 5920 | W16: 5000
B17: Jun 2027 | C17: =Loans!$C$5 -> 110000 | D17: =SUM(H17:X17) -> 93828 | E17: =IF(B17="","",SUMIFS('June 2026 Expenses'!C:C, 'June 2026 Expenses'!A:A, ">="&DATEVALUE(B17), 'June 2026 Expenses'!A:A, "<="&EOMONTH(DATEVALUE(B17), 0))) -> 0 | F17: =C17-D17-E17 -> 16172 | G17: Car purchase window opens! | H17: 26494 | I17: 11839 | J17: 15250 | L17: 4500 | M17: 5000 | P17: 2600 | Q17: 2680 | R17: 5390 | S17: 3235 | U17: 5920 | V17: 5920 | W17: 5000
B18: Jul 2027 | C18: =Loans!$C$5 -> 110000 | D18: =SUM(H18:X18) -> 93828 | E18: =IF(B18="","",SUMIFS('June 2026 Expenses'!C:C, 'June 2026 Expenses'!A:A, ">="&DATEVALUE(B18), 'June 2026 Expenses'!A:A, "<="&EOMONTH(DATEVALUE(B18), 0))) -> 0 | F18: =C18-D18-E18 -> 16172 | G18: TVS Excel closes ✓ | DIO Loan closes ✓ | H18: 26494 | I18: 11839 | J18: 15250 | L18: 4500 | M18: 5000 | P18: 2600 | Q18: 2680 | R18: 5390 | S18: 3235 | U18: 5920 | V18: 5920 | W18: 5000
B19: Aug 2027 | C19: =Loans!$C$5 -> 110000 | D19: =SUM(H19:X19) -> 84328 | E19: =IF(B19="","",SUMIFS('June 2026 Expenses'!C:C, 'June 2026 Expenses'!A:A, ">="&DATEVALUE(B19), 'June 2026 Expenses'!A:A, "<="&EOMONTH(DATEVALUE(B19), 0))) -> 0 | F19: =C19-D19-E19 -> 25672 | H19: 26494 | I19: 11839 | J19: 15250 | P19: 2600 | Q19: 2680 | R19: 5390 | S19: 3235 | U19: 5920 | V19: 5920 | W19: 5000
B20: Sep 2027 | C20: =Loans!$C$5 -> 110000 | D20: =SUM(H20:X20) -> 84328 | E20: =IF(B20="","",SUMIFS('June 2026 Expenses'!C:C, 'June 2026 Expenses'!A:A, ">="&DATEVALUE(B20), 'June 2026 Expenses'!A:A, "<="&EOMONTH(DATEVALUE(B20), 0))) -> 0 | F20: =C20-D20-E20 -> 25672 | H20: 26494 | I20: 11839 | J20: 15250 | P20: 2600 | Q20: 2680 | R20: 5390 | S20: 3235 | U20: 5920 | V20: 5920 | W20: 5000
B21: Oct 2027 | C21: =Loans!$C$5 -> 110000 | D21: =SUM(H21:X21) -> 84328 | E21: =IF(B21="","",SUMIFS('June 2026 Expenses'!C:C, 'June 2026 Expenses'!A:A, ">="&DATEVALUE(B21), 'June 2026 Expenses'!A:A, "<="&EOMONTH(DATEVALUE(B21), 0))) -> 0 | F21: =C21-D21-E21 -> 25672 | G21: ESAF 2 closes ✓ | H21: 26494 | I21: 11839 | J21: 15250 | P21: 2600 | Q21: 2680 | R21: 5390 | S21: 3235 | U21: 5920 | V21: 5920 | W21: 5000
B22: Nov 2027 | C22: =Loans!$C$5 -> 110000 | D22: =SUM(H22:X22) -> 81093 | E22: =IF(B22="","",SUMIFS('June 2026 Expenses'!C:C, 'June 2026 Expenses'!A:A, ">="&DATEVALUE(B22), 'June 2026 Expenses'!A:A, "<="&EOMONTH(DATEVALUE(B22), 0))) -> 0 | F22: =C22-D22-E22 -> 28907 | H22: 26494 | I22: 11839 | J22: 15250 | P22: 2600 | Q22: 2680 | R22: 5390 | U22: 5920 | V22: 5920 | W22: 5000
B23: Dec 2027 | C23: =Loans!$C$5 -> 110000 | D23: =SUM(H23:X23) -> 81093 | E23: =IF(B23="","",SUMIFS('June 2026 Expenses'!C:C, 'June 2026 Expenses'!A:A, ">="&DATEVALUE(B23), 'June 2026 Expenses'!A:A, "<="&EOMONTH(DATEVALUE(B23), 0))) -> 0 | F23: =C23-D23-E23 -> 28907 | H23: 26494 | I23: 11839 | J23: 15250 | P23: 2600 | Q23: 2680 | R23: 5390 | U23: 5920 | V23: 5920 | W23: 5000
B24: Jan 2028 | C24: =Loans!$C$5 -> 110000 | D24: =SUM(H24:X24) -> 81093 | E24: =IF(B24="","",SUMIFS('June 2026 Expenses'!C:C, 'June 2026 Expenses'!A:A, ">="&DATEVALUE(B24), 'June 2026 Expenses'!A:A, "<="&EOMONTH(DATEVALUE(B24), 0))) -> 0 | F24: =C24-D24-E24 -> 28907 | G24: SBI Personal closes ✓ | ESAF 1 closes ✓ | H24: 26494 | I24: 11839 | J24: 15250 | P24: 2600 | Q24: 2680 | R24: 5390 | U24: 5920 | V24: 5920 | W24: 5000
B25: Feb 2028 | C25: =Loans!$C$5 -> 110000 | D25: =SUM(H25:X25) -> 63864 | E25: =IF(B25="","",SUMIFS('June 2026 Expenses'!C:C, 'June 2026 Expenses'!A:A, ">="&DATEVALUE(B25), 'June 2026 Expenses'!A:A, "<="&EOMONTH(DATEVALUE(B25), 0))) -> 0 | F25: =C25-D25-E25 -> 46136 | H25: 26494 | J25: 15250 | P25: 2600 | Q25: 2680 | U25: 5920 | V25: 5920 | W25: 5000
B26: Mar 2028 | C26: =Loans!$C$5 -> 110000 | D26: =SUM(H26:X26) -> 63864 | E26: =IF(B26="","",SUMIFS('June 2026 Expenses'!C:C, 'June 2026 Expenses'!A:A, ">="&DATEVALUE(B26), 'June 2026 Expenses'!A:A, "<="&EOMONTH(DATEVALUE(B26), 0))) -> 0 | F26: =C26-D26-E26 -> 46136 | G26: Samasta 3 closes ✓ | H26: 26494 | J26: 15250 | P26: 2600 | Q26: 2680 | U26: 5920 | V26: 5920 | W26: 5000
B27: Apr 2028 | C27: =Loans!$C$5 -> 110000 | D27: =SUM(H27:X27) -> 61264 | E27: =IF(B27="","",SUMIFS('June 2026 Expenses'!C:C, 'June 2026 Expenses'!A:A, ">="&DATEVALUE(B27), 'June 2026 Expenses'!A:A, "<="&EOMONTH(DATEVALUE(B27), 0))) -> 0 | F27: =C27-D27-E27 -> 48736 | G27: Samasta 4 closes ✓ | H27: 26494 | J27: 15250 | Q27: 2680 | U27: 5920 | V27: 5920 | W27: 5000
B28: May 2028 | C28: =Loans!$C$5 -> 110000 | D28: =SUM(H28:X28) -> 58584 | E28: =IF(B28="","",SUMIFS('June 2026 Expenses'!C:C, 'June 2026 Expenses'!A:A, ">="&DATEVALUE(B28), 'June 2026 Expenses'!A:A, "<="&EOMONTH(DATEVALUE(B28), 0))) -> 0 | F28: =C28-D28-E28 -> 51416 | H28: 26494 | J28: 15250 | U28: 5920 | V28: 5920 | W28: 5000
B29: Jun 2028 | C29: =Loans!$C$5 -> 110000 | D29: =SUM(H29:X29) -> 58584 | E29: =IF(B29="","",SUMIFS('June 2026 Expenses'!C:C, 'June 2026 Expenses'!A:A, ">="&DATEVALUE(B29), 'June 2026 Expenses'!A:A, "<="&EOMONTH(DATEVALUE(B29), 0))) -> 0 | F29: =C29-D29-E29 -> 51416 | G29: Aasirvad (x2) closes ✓ | H29: 26494 | J29: 15250 | U29: 5920 | V29: 5920 | W29: 5000
B30: Jul 2028 | C30: =Loans!$C$5 -> 110000 | D30: =SUM(H30:X30) -> 46744 | E30: =IF(B30="","",SUMIFS('June 2026 Expenses'!C:C, 'June 2026 Expenses'!A:A, ">="&DATEVALUE(B30), 'June 2026 Expenses'!A:A, "<="&EOMONTH(DATEVALUE(B30), 0))) -> 0 | F30: =C30-D30-E30 -> 63256 | H30: 26494 | J30: 15250 | W30: 5000
B31: Aug 2028 | C31: =Loans!$C$5 -> 110000 | D31: =SUM(H31:X31) -> 46744 | E31: =IF(B31="","",SUMIFS('June 2026 Expenses'!C:C, 'June 2026 Expenses'!A:A, ">="&DATEVALUE(B31), 'June 2026 Expenses'!A:A, "<="&EOMONTH(DATEVALUE(B31), 0))) -> 0 | F31: =C31-D31-E31 -> 63256 | H31: 26494 | J31: 15250 | W31: 5000
B32: Sep 2028 | C32: =Loans!$C$5 -> 110000 | D32: =SUM(H32:X32) -> 46744 | E32: =IF(B32="","",SUMIFS('June 2026 Expenses'!C:C, 'June 2026 Expenses'!A:A, ">="&DATEVALUE(B32), 'June 2026 Expenses'!A:A, "<="&EOMONTH(DATEVALUE(B32), 0))) -> 0 | F32: =C32-D32-E32 -> 63256 | H32: 26494 | J32: 15250 | W32: 5000
B33: Oct 2028 | C33: =Loans!$C$5 -> 110000 | D33: =SUM(H33:X33) -> 46744 | E33: =IF(B33="","",SUMIFS('June 2026 Expenses'!C:C, 'June 2026 Expenses'!A:A, ">="&DATEVALUE(B33), 'June 2026 Expenses'!A:A, "<="&EOMONTH(DATEVALUE(B33), 0))) -> 0 | F33: =C33-D33-E33 -> 63256 | H33: 26494 | J33: 15250 | W33: 5000
B34: Nov 2028 | C34: =Loans!$C$5 -> 110000 | D34: =SUM(H34:X34) -> 46744 | E34: =IF(B34="","",SUMIFS('June 2026 Expenses'!C:C, 'June 2026 Expenses'!A:A, ">="&DATEVALUE(B34), 'June 2026 Expenses'!A:A, "<="&EOMONTH(DATEVALUE(B34), 0))) -> 0 | F34: =C34-D34-E34 -> 63256 | H34: 26494 | J34: 15250 | W34: 5000
B35: Dec 2028 | C35: =Loans!$C$5 -> 110000 | D35: =SUM(H35:X35) -> 46744 | E35: =IF(B35="","",SUMIFS('June 2026 Expenses'!C:C, 'June 2026 Expenses'!A:A, ">="&DATEVALUE(B35), 'June 2026 Expenses'!A:A, "<="&EOMONTH(DATEVALUE(B35), 0))) -> 0 | F35: =C35-D35-E35 -> 63256 | G35: Other Loan closes ✓ | H35: 26494 | J35: 15250 | W35: 5000
B36: Jan 2029 | C36: =Loans!$C$5 -> 110000 | D36: =SUM(H36:X36) -> 41744 | E36: =IF(B36="","",SUMIFS('June 2026 Expenses'!C:C, 'June 2026 Expenses'!A:A, ">="&DATEVALUE(B36), 'June 2026 Expenses'!A:A, "<="&EOMONTH(DATEVALUE(B36), 0))) -> 0 | F36: =C36-D36-E36 -> 68256 | H36: 26494 | J36: 15250
B37: Feb 2029 | C37: =Loans!$C$5 -> 110000 | D37: =SUM(H37:X37) -> 41744 | E37: =IF(B37="","",SUMIFS('June 2026 Expenses'!C:C, 'June 2026 Expenses'!A:A, ">="&DATEVALUE(B37), 'June 2026 Expenses'!A:A, "<="&EOMONTH(DATEVALUE(B37), 0))) -> 0 | F37: =C37-D37-E37 -> 68256 | H37: 26494 | J37: 15250
B38: Mar 2029 | C38: =Loans!$C$5 -> 110000 | D38: =SUM(H38:X38) -> 41744 | E38: =IF(B38="","",SUMIFS('June 2026 Expenses'!C:C, 'June 2026 Expenses'!A:A, ">="&DATEVALUE(B38), 'June 2026 Expenses'!A:A, "<="&EOMONTH(DATEVALUE(B38), 0))) -> 0 | F38: =C38-D38-E38 -> 68256 | H38: 26494 | J38: 15250
B39: Apr 2029 | C39: =Loans!$C$5 -> 110000 | D39: =SUM(H39:X39) -> 41744 | E39: =IF(B39="","",SUMIFS('June 2026 Expenses'!C:C, 'June 2026 Expenses'!A:A, ">="&DATEVALUE(B39), 'June 2026 Expenses'!A:A, "<="&EOMONTH(DATEVALUE(B39), 0))) -> 0 | F39: =C39-D39-E39 -> 68256 | H39: 26494 | J39: 15250
B40: May 2029 | C40: =Loans!$C$5 -> 110000 | D40: =SUM(H40:X40) -> 41744 | E40: =IF(B40="","",SUMIFS('June 2026 Expenses'!C:C, 'June 2026 Expenses'!A:A, ">="&DATEVALUE(B40), 'June 2026 Expenses'!A:A, "<="&EOMONTH(DATEVALUE(B40), 0))) -> 0 | F40: =C40-D40-E40 -> 68256 | H40: 26494 | J40: 15250
B41: Jun 2029 | C41: =Loans!$C$5 -> 110000 | D41: =SUM(H41:X41) -> 41744 | E41: =IF(B41="","",SUMIFS('June 2026 Expenses'!C:C, 'June 2026 Expenses'!A:A, ">="&DATEVALUE(B41), 'June 2026 Expenses'!A:A, "<="&EOMONTH(DATEVALUE(B41), 0))) -> 0 | F41: =C41-D41-E41 -> 68256 | G41: SMFG 0% foreclosure from here | H41: 26494 | J41: 15250
...

Sheet June 2026 Expenses
A1: Monthly Life Expenses
A3: Month | B3: Category | C3: Amount | D3: Notes
A4: 46174 | B4: TO Amma | C4: 1000 | D4: 46174
A5: 46175 | B5: Siva Priya Loan | C5: 12000 | D5: 46174
A6: 46176 | B6: APPA | C6: 2000 | D6: 46176
A7: 46177 | B7: AMMA | C7: 3000 | D7: 46177
A8: 46178 | B8: AMMA | C8: 1500 | D8: 46177
A9: 46179 | B9: HOME EXPENSE | C9: 585 | D9: 46179
A10: 46180 | B10: GRINDER & FAN | C10: 4208 | D10: EMI FROM JULY 1740
A11: 46181 | B11: APPA | C11: 2000
A12: 46182 | B12: Thandal | C12: 2000 | D12: From Raghuls 6250 2 June
A13: 46174 | B13: D Mart | C13: 9975 | D13: Naresh gave 11,000. 6/2/2026
A14: 46174 | B14: snacks | C14: 185 | D14: Naresh gave 11,000. 6/2/2026
A15: 46174 | B15: Veera kattu potathu | C15: 650 | D15: Naresh gave 11,000. 6/2/2026
A16: 46174 | B16: TVS | C16: 5077 | D16: (4K from Raghuls& 1k Naresh). 6/4/2026
A17: 46174 | B17: Home expense | C17: 716 | D17: From Gold Loan. 5 June
A18: 46175 | B18: Veera Scooty EMI | C18: 5000 | D18: From Gold Loan. 5 June
A19: 46176 | B19: எண்ணெய் செட்டியார் | C19: 2000 | D19: From Gold Loan. 5 June
A20: 46177 | B20: Plumper | C20: 240 | D20: From Gold Loan. 5 June
A21: 46178 | B21: Sivapriya Tablet | C21: 512 | D21: From Gold Loan. 6 June
A22: 46179 | B22: Veera Hospital Expenses | C22: 3000 | D22: From Gold Loan. 6 June
A23: 46180 | B23: Equitas Home loan | C23: 15230 | D23: From Gold Loan. 6 June
... A29: 46186 | B29: ESAF | C29: 9855 | D29: 10,000 from Naresh
A30: 46187 | B30: Net Recharge | C30: 590 | D30: 46181
A31: 46188 | B31: Appa | C31: 2000 | D31: 46184
A32: 46189 | B32: AMMA - Microloan | C32: 6000 | D32: 46191
A33: 46174 | B33: Cylinder | C33: 1070 | D33: 46193
A34: 46174 | B34: Other loan | C34: 5000 | D34: 46193
A35: 46174 | B35: Movie | C35: 850 | D35: 46194
A36: 46174 | B36: Mat | C36: 220 | D36: 46194
A37: 46174 | B37: Gold coin -2 grams | C37: 27500 | D37: credit card. 25 June

Sheet Gold Loan
B2: Gold Loan Tracker
B4: Gram | C4: Interest in Bank | D4: Bank Name | E4: Account Holder | F4: Loan Amount | G4: Date of Kept | H4: Interest to Pay
B5: 55.8 | C5: 0.11 | D5: CUB | E5: Mani Mozhi | F5: 391560 | G5: 46010 | H5: =IF(OR(ISBLANK(F5), ISBLANK(G5), ISBLANK(C5)), 0, F5 * C5 * (TODAY() - G5) / 365) -> 35047.302
B6: 30 | C6: 0.1 | D6: CUB | E6: Krishnamoorthy | F6: 229500 | G6: 45966 | H6: =IF(OR(ISBLANK(F6), ISBLANK(G6), ISBLANK(C6)), 0, F6 * C6 * (TODAY() - G6) / 365) -> 21440.959
B7: 36.9 | C7: 0.105 | D7: CUB | E7: SivaPriya | F7: 300000 | G7: 46169 | H7: =IF(OR(ISBLANK(F7), ISBLANK(G7), ISBLANK(C7)), 0, F7 * C7 * (TODAY() - G7) / 365) -> 11909.589
B8: 15 | D8: CUB | E8: SivaPriya | F8: 135000 | G8: 46178 | H8: =IF(OR(ISBLANK(F8), ISBLANK(G8), ISBLANK(C8)), 0, F8 * C8 * (TODAY() - G8) / 365) -> 0
D9: CUB | E9: NareshKumar | F9: 297698 | G9: 46035 | H9: =IF(OR(ISBLANK(F9), ISBLANK(G9), ISBLANK(C9)), 0, F9 * C9 * (TODAY() - G9) / 365) -> 0
H10: =IF(OR(ISBLANK(F10), ISBLANK(G10)), "", F10 * (C10/100) * (TODAY() - G10) / 365)
H11: =IF(OR(ISBLANK(F11), ISBLANK(G11)), "", F11 * (C11/100) * (TODAY() - G11) / 365)
H12: =IF(OR(ISBLANK(F12), ISBLANK(G12)), "", F12 * (C12/100) * (TODAY() - G12) / 365)
H13: =IF(OR(ISBLANK(F13), ISBLANK(G13)), "", F13 * (C13/100) * (TODAY() - G13) / 365)
H14: =IF(OR(ISBLANK(F14), ISBLANK(G14)), "", F14 * (C14/100) * (TODAY() - G14) / 365)
H15: =IF(OR(ISBLANK(F15), ISBLANK(G15)), "", F15 * (C15/100) * (TODAY() - G15) / 365)
H16: =IF(OR(ISBLANK(F16), ISBLANK(G16)), "", F16 * (C16/100) * (TODAY() - G16) / 365)
H17: =IF(OR(ISBLANK(F17), ISBLANK(G17)), "", F17 * (C17/100) * (TODAY() - G17) / 365)
H18: =IF(OR(ISBLANK(F18), ISBLANK(G18)), "", F18 * (C18/100) * (TODAY() - G18) / 365)
H19: =IF(OR(ISBLANK(F19), ISBLANK(G19)), "", F19 * (C19/100) * (TODAY() - G19) / 365)
H20: =IF(OR(ISBLANK(F20), ISBLANK(G20)), "", F20 * (C20/100) * (TODAY() - G20) / 365)
H21: =IF(OR(ISBLANK(F21), ISBLANK(G21)), "", F21 * (C21/100) * (TODAY() - G21) / 365)
... H96: =IF(OR(ISBLANK(F96), ISBLANK(G96)), "", F96 * (C96/100) * (TODAY() - G96) / 365)

Sheet Tips to Close Faster
B1: Tips to Close All Loans Faster
B2: Follow these steps in order — highest impact first
B4: 1 | C4: URGENT — Fix Credit Card NOW | D4: Call your bank immediately. The credit card ₹18,972/month charges 36–48% interest — the most expensive debt you have. Ask to convert to a personal loan at 12–15% or settle the ₹97,110 balance in one shot. Every month you wait costs ₹3,000–4,000 extra in interest alone.
B5: 2 | C5: Stop taking any new loans | D5: Your EMIs (₹1,15,135) already exceed your combined income (₹1,10,000). Even one new EMI will push you into serious default risk. No new microfinance, personal, or vehicle loan until at least 2027.
B6: 3 | C6: Jul 2026 — Samasta 2 closes (₹2,650 freed) | D6: When Samasta 2 ends in July 2026, DO NOT spend that ₹2,650. Immediately redirect it to pay extra on the Credit Card principal. This discipline of 'redirecting freed EMIs' is the most powerful debt-clearing tool you have.
B7: 4 | C7: Oct 2026 — ESAF 2 closes (₹3,235 freed) | D7: Add this ₹3,235 to your Credit Card or SMFG extra payment. By Oct 2026 you'll have ₹5,885/month extra cash if you stay disciplined.
B8: 5 | C8: Nov–Dec 2026 — TVS + DIO close (₹10,725 freed) | D8: Both vehicle loans end around the same time, freeing ₹10,725/month. Combined with previous savings, you'll have ~₹16,610 extra per month. Use ALL of this toward SMFG prepayment. Call SMFG and ask about part-payment options (note: SMFG only allows FULL foreclosure, not partial — so build a fund for that).
B9: 6 | C9: Jan 2027 — ESAF 1 closes (₹5,390 freed) | D9: Another ₹5,390/month freed. Now you have ~₹22,000 extra monthly. Start a dedicated 'Loan Closure Fund' savings account. Target ₹8–10L in this account for SMFG foreclosure.
B10: 7 | C10: Mar 2027 — SBI + Samasta 1 close (₹15,000 freed!) | D10: This is your biggest milestone. SBI Personal Loan (₹11,839) and Samasta 1 (₹3,150) both close around March 2027, freeing ~₹15,000/month. Your total monthly savings now hit ₹37,000+. This is when you should buy your car (₹12–15L, EMI ₹18–22K stays comfortable).
B11: 8 | C11: Jun 2027 — Car Purchase Window | D11: By June 2027 your free cash is ₹30,000+/month. Target a ₹12–15L car (Tata Nexon / Hyundai Venue / Maruti Brezza base). Save ₹2–3L as down payment from Apr–Jun 2027 freed cash. EMI of ~₹20–24K will be comfortable. Avoid the ₹23L car until 2028.
B12: 9 | C12: Equitas Home Loan — prepay aggressively (ZERO penalty) | D12: Equitas home loan has NO prepayment penalty on floating rate. Every extra rupee you pay reduces principal directly and saves interest. From 2027 onwards, put ₹10,000–15,000/month extra toward this loan. You can close it 2–3 years early and save ₹2–3L in interest. Call Equitas: 1800-103-2977 to request a revised amortization schedule.
B13: 10 | C13: SMFG Loan — wait for 36 EMIs then foreclose | D13: SMFG charges 7% foreclosure fee before 18 EMIs, 5% before 24, 3% before 36, and ZERO from 36 EMIs onwards (around Jun 2029). Build your foreclosure fund now. By Jun 2029 the outstanding will be ~₹7–8L. Close it in one shot with zero penalty and save years of 20% interest.
B14: 11 | C14: The Redirect Rule — most important habit | D14: Every time a loan closes, NEVER increase spending. Redirect 100% of that freed EMI to the next target loan. This snowball approach means each closure speeds up the next one. Example: Jul 2026 Samasta closes → add ₹2,650 to CC. Oct 2026 ESAF closes → add ₹3,235 more. By Mar 2027 you have ₹37K+ extra monthly without earning more.
B15: 12 | C15: Emergency Fund — build ₹50,000 buffer | D15: With this many loans, one missed payment can trigger a penalty chain. Keep ₹30,000–50,000 in a savings account untouched as a safety net. Use Equitas Bank savings account (no minimum balance for basic accounts). This prevents you from needing emergency loans which would restart the cycle.
... B18: 15 | C18: Key contacts to call NOW | D18: Credit Card: Call your card bank and ask for balance-to-loan conversion. SMFG: 1800-103-6001 — ask for foreclosure statement when ready. Equitas Home Loan: 1800-103-2977 — ask for part-payment process. SBI: Visit nearest branch with loan account number for prepayment.
B20: MILESTONE CALENDAR
B21: Month | C21: Event | D21: Action / Impact
B22: Jul 2026 | C22: Samasta 2 ends | D22: ₹2,650/mo freed → redirect to Credit Card
B23: Oct 2026 | C23: ESAF 2 ends | D23: ₹3,235/mo freed → total ₹5,885 extra
B24: Nov 2026 | C24: TVS + DIO end | D24: ₹10,725/mo freed → total ₹16,610 extra
B25: Jan 2027 | C25: ESAF 1 ends | D25: ₹5,390/mo freed → total ₹22,000 extra
B26: Mar 2027 | C26: SBI + Samasta 1 end | D26: ₹15,000/mo freed → total ₹37,000 extra!
B27: Jun 2027 | C27: Car purchase window | D27: Buy ₹12–15L car — EMI fits comfortably
B28: Feb 2027 | C28: ESAF 3 ends | D28: More microfinance cleared
B29: Oct 2027 | C29: ESAF 2 + Samasta 1 cleared | D29: Almost all micro loans done
B30: Jan 2028 | C30: SBI fully closed | D30: Major milestone — only SMFG + Home remain
B31: Apr 2028 | C31: All microfinance cleared | D31: ₹57K/mo free — only 2 loans left
B32: Jun 2029 | C32: SMFG 0% foreclosure zone | D32: Close SMFG loan with ZERO penalty!
B33: Dec 2030 | C33: Equitas Home Loan ends | D33: Debt FREE! (or close earlier with prepayment)

Sheet General
A1: Date | B1: Expense | C1: Amount
A2: 46165 | B2: Amma | C2: 10000
A3: 46166 | B3: Credit card | C3: 19000
A4: 46168 | B4: veera Licence | C4: 2500
A5: 46169 | B5: Bank gold interest | C5: 29050
A6: 46169 | B6: Mahesh | C6: 100
A7: 46169 | B7: Petrol | C7: 300
A8: 46169 | B8: Snacks | C8: 370
A9: 46169 | B9: Veera Dress | C9: 2494
A10: 46169 | B10: Thiliban | C10: 5000
A11: 46169 | B11: Gold stud | C11: 29000 | D11: Old gold(2grams) | E11: 24000
A12: 46169 | B12: Auto | C12: 400 | D12: Total amount | E12: 53000
A13: 46169 | B13: Amma Tablet | C13: 600
A14: 46170
A22: Loan name | B22: Date | C22: Name | D22: Amount | E22: Last date
A23: Samasta | B23: 3rd Thurs of every month | C23: Kalyani | D23: 3150 | E23: 46464
A24: Samasta | B24: 3rd Thurs of every month | C24: Sangeetha | D24: 2650 | E24: 46219
A25: Samasta | B25: 3rd Thurs of every month | C25: Priya | D25: 2600 | E25: 46828
A26: Samasta | B26: 3rd Thurs of every month | C26: Thavamani | D26: 2680 | E26: 46863
A27: ESAF | B27: 2nd Wednesday | C27: Manimozhi | D27: 5390 | E27: 46764
A28: ESAF | B28: 2nd Wednesday | C28: Sivapriya | D28: 3235 | E28: 46673
A29: ESAF | B29: 2nd Wednesday | C29: Pazhaniyammal | D29: 1230 | E29: 14 due
A30: Aasirvad | C30: Kalyani | D30: 2970
A31: Aasirvad | C31: Manimozhi | D31: 2970
A32: Arivazhagi loan | B32: 20th of every month | D32: 5000 | E32: c
A42: Debt & EMI Tracker
A45: Loan Name | B45: Principal Amount | C45: Interest Rate (%) | D45: EMI | E45: Total EMIs | F45: EMIs Paid | G45: Remaining EMIs | H45: Total Paid | I45: Remaining Balance | J45: Total Interest
A46: SMFG Personal Loan - Naresh | B46: 1000000 | C46: 0.2 | D46: =IF(AND(B46<>"", C46<>"", E46<>""), PMT(C46/12, E46, -B46), "") -> 26493.884 | E46: 60 | F46: 0 | G46: =IF(E46="", "", E46 - F46) -> 60 | H46: =IF(D46="", "", D46 * F46) -> 0 | I46: =IF(G46="", "", IFERROR(PV(C46/12, G46, -D46), "")) -> 1000000 | J46: =IF(AND(D46<>"", E46<>""), (D46 * E46) - B46, "") -> 589633.02
A47: SBI Personal Loan - SivaPriya | B47: 596000 | C47: 0.126 | D47: =IF(AND(B47<>"", C47<>"", E47<>""), PMT(C47/12, E47, -B47), 11839) -> 11838.711 | E47: 72 | F47: 52 | G47: =IF(E47="", "", E47 - F47) -> 20 | H47: =IF(D47="", "", D47 * F47) -> 615612.97 | I47: =IF(G47="", "", IFERROR(PV(C47/12, G47, -D47), "")) -> 212564.4 | J47: =IF(AND(D47<>"", E47<>""), (D47 * E47) - B47, "") -> 256387.19
A48: Equitas Home Loan - (APPA)Krishnamoorthy | D48: =IF(AND(B48<>"", C48<>"", E48<>""), PMT(C48/12, E48, -B48), 15250) -> 15250 | F48: 0 | G48: =IF(E48="", "", E48 - F48) | H48: =IF(D48="", "", D48 * F48) -> 0 | I48: =IF(G48="", "", IFERROR(PV(C48/12, G48, -D48), "")) | J48: =IF(AND(D48<>"", E48<>""), (D48 * E48) - B48, "")
A49: Credit Card | B49: 97110 | D49: =IF(AND(B49<>"", C49<>"", E49<>""), PMT(C49/12, E49, -B49), 18972) -> 18972 | F49: 0 | G49: =IF(E49="", "", E49 - F49) | H49: =IF(D49="", "", D49 * F49) -> 0 | I49: =IF(G49="", "", IFERROR(PV(C49/12, G49, -D49), "")) | J49: =IF(AND(D49<>"", E49<>""), (D49 * E49) - B49, "")
A50: TVS Excel - (APPA)Krishnamoorthy | B50: 83419 | C50: 0.12 | D50: =IF(AND(B50<>"", C50<>"", E50<>""), PMT(C50/12, E50, -B50), 4627) -> 5087.0615 | E50: 18 | F50: 3 | G50: =IF(E50="", "", E50 - F50) -> 15 | H50: =IF(D50="", "", D50 * F50) -> 15261.184 | I50: =IF(G50="", "", IFERROR(PV(C50/12, G50, -D50), "")) -> 70532.374 | J50: =IF(AND(D50<>"", E50<>""), (D50 * E50) - B50, "") -> 8148.1062
A51: DIO | B51: 149100 | C51: 0.1 | D51: =IF(AND(B51<>"", C51<>"", E51<>""), PMT(C51/12, E51, -B51), 4627) -> 5637.6813 | E51: 30 | F51: 15 | G51: =IF(E51="", "", E51 - F51) -> 15 | H51: =IF(D51="", "", D51 * F51) -> 84565.219 | I51: =IF(G51="", "", IFERROR(PV(C51/12, G51, -D51), "")) -> 79184.086 | J51: =IF(AND(D51<>"", E51<>""), (D51 * E51) - B51, "") -> 20030.438
A52: Inverter | D52: =IF(AND(B52<>"", C52<>"", E52<>""), PMT(C52/12, E52, -B52), 3850) -> 3850 | F52: 0 | G52: =IF(E52="", "", E52 - F52) | H52: =IF(D52="", "", D52 * F52) -> 0 | I52: =IF(G52="", "", IFERROR(PV(C52/12, G52, -D52), "")) | J52: =IF(AND(D52<>"", E52<>""), (D52 * E52) - B52, "")
A61: Date | B61: Type of expenditure | C61: Amount | D61: Paid/unpaid | E61: Balance as of the last EMI | F61: Incomes and Borrowings | G61: Amount | I61: Summary
A62: 46143 | B62: Sivapriya Loan | C62: 11839 | D62: TRUE | E62: 2,02,625.00 | F62: Naresh salary | G62: 71000 | I62: Total Expenses | J62: =SUM(C62:C1000) -> 84657
A63: 46144 | B63: Inverter EMI | C63: 3850 | D63: TRUE | E63: EMI over | I63: Total Paid | J63: =SUMIFS(C62:C1000, D62:D1000, TRUE) -> 50435
A64: 46145 | B64: TVS EXCEL EMI | C64: 4627 | D64: TRUE | I64: Total Unpaid | J64: =SUMIFS(C62:C1000, D62:D1000, FALSE) -> 34222
A65: 46147 | B65: DIO EMI(Scotty) | C65: 5000 | D65: TRUE | I65: Total Incomes | J65: =SUM(G62:G1000) -> 71000
A66: 46167 | B66: Credit card | C66: 18972 | D66: FALSE | E66: 97110 | I66: Net Balance | J66: =J65-J62 -> -13657
...

Sheet July 2026 Expense 
A1: Date | B1: Category Expense | C1: Amount | D1: Notes
A2: 46060 | B2: Sivapriya Loan | C2: 12000 | D2: 20,000 from Naresh
A3: 46060 | B3: Excel EMI | C3: 4600 | D3: Balance-4k Appa
A4: 46180 | B4: Chicken noodles | C4: 110
A5: 46210 | B5: ESAF | C5: 13600 | D5: From Gold Loan 23,700
A6: 46241 | B6: Pattu புடவை+covering chain(700+2000) | C6: 2700
A7: 46241 | B7: Amma in hand | C7: 2000 | D7: Balance 5000 in Amma account
A8: 13-07-2026 | B8: Equitas Home Loan | C8: 15500 | D8: 50,000 from Naresh
A9: 14-07-2026 | B9: வார தண்டல் | C9: 2000
A10: 16-07-2026 | B10: samasta | C10: 18700
A11: 17-07-2026 | B11: அஞ்சு | C11: 4000
A12: 19-07-2026 | B12: Dress-Hari&அப்பா(1590+2100) | C12: 3690
A13: 19-07-2026 | B13: Sivapriya Dress(2789+2300) | C13: 5089
A14: 20-07-2026 | B14: Arivazhagi Loan | C14: 5210
A15: 20-07-2026 | B15: வார தண்டல் | C15: 1250
A16: 20-07-2026 | B16: தட்டு for manja thanni | C16: 1500
A17: 20-07-2026 | B17: Amma eye hospital | C17: 320
A18: 20-07-2026 | B18: Auto+Poo+snacks(400+80+210) | C18: 690
A19: 22-07-2026 | D19: நரேஷ்(50,000+10,000)
A20: 24-07-2026 | B20: Credit card | C20: 12200
A21: 25-07-2026 | B21: Fruits+Auto(2600+400) | C21: 3000
A22: 26-07-2026 | B22: Manja thanni varisai | C22: 30000
A23: 26-07-2026 | B23: Van | C23: 3200
A24: 27-07-2026 | B24: Aashirvad | C24: 6000
A25: 28-07-2026 | B25: Thandal | C25: 2000 | D25: Balance 4k
B27: Total | C27: 1,49,359

Sheet August 2026
A1: DATE | B1: CREDIT Amount | C1: Expense | D1: Amount | E1: Note
A2: 31-07-2026 | B2: 20000 | E2: Naresh salary
A3: 31-07-2026 | B3: 40000 | E3: Veera salary
A4: 46030 | C4: Sivapriya Loan | D4: 12000
A5: 46089 | C5: Appa Bike | D5: 4650
A6: 46030 | C6: Groceries | D6: 1150
A7: 46030 | C7: Fish prawn | D7: 850
A8: 46030 | C8: Amma (in hand) | D8: 3000 | E8: (Balance from last month)
A9: 46061 | C9: Sivapriya | D9: 300 | E9: Balance-42,000
